Workbook

Sheet Comentario
A2: El IPC de abril registró una variación mensual de 1,2%, llevando la inflación anual a 4,0%, por encima de las expectativas del mercado. El alza estuvo impulsada principalmente por los combustibles y su traspaso al componente de transporte. El componente volátil de energía acumuló un avance mensual de 12,9%, reflejando especialmente los incrementos en los precios de la gasolina y el diésel asociados al shock energético observado a fines de marzo. La inflación subyacente continuó mostrando una dinámica relativamente contenida, con un aumento de 0,5% mensual y 3,5% anual. Tanto los servicios como los bienes subyacentes mantuvieron variaciones acotadas, sin señales relevantes de efectos de segunda vuelta asociados a una aceleración de la demanda. Si bien el traspaso del shock en combustibles sigue siendo limitado fuera de los componentes más volátiles, su impacto continuará siendo monitoreado en los próximos meses. Por su parte, el Banco Central mantuvo la tasa de política monetaria en 4,5%, manteniendo una postura cautelosa ante la incertidumbre asociada a la evolución del conflicto en Medio Oriente, la trayectoria del precio del petróleo y sus potenciales efectos sobre la convergencia inflacionaria.

Sheet Datos ICP (2)
A1: CLICP Index | F1: Cuota Liquidez | AD1: ICP | AE1: Ene | AF1: Feb | AG1: Mar | AH1: Abr | AI1: May | AJ1: Jun | AK1: Jul | AL1: Ago | AM1: Sep | AN1: Oct | AO1: Nov | AP1: Dic | AQ1: Total Año
A2: Fecha | B2: ICP | D2: ICP Norm. | J2: Fondo Liquidez Activa | K2: 8730-0 | M2: Competencia Relevante (*) | P2: Ene | Q2: Feb | R2: Mar | S2: Abr | T2: May | U2: Jun | V2: Jul | W2: Ago | X2: Sep | Y2: Oct | Z2: Nov | AA2: Dic | AD2: 2006 | AQ2: =AA3/N3-1 -> -1
A3: 38717 | B3: 10953.14 | K3: SERIE E | N3: =B3 -> 10953.14 | O3: 2006 | AD3: 2007
A4: 38748 | B4: 10996.85 | C4: =(B4/B3-1)/(A4-A3)*30 -> 0.0038619063 | K4: BCI EFICIENTE | O4: 2007 | AD4: 2008
A5: 38776 | B5: 11035.11 | C5: =(B5/B4-1)/(A5-A4)*30 -> 0.0037276909 | O5: 2008 | AD5: 2009
A6: 38807 | B6: 11078.66 | C6: =(B6/B5-1)/(A6-A5)*30 -> 0.0038191881 | O6: 2009 | AD6: 2010
A7: 38835 | B7: 11118.82 | C7: =(B7/B6-1)/(A7-A6)*30 -> 0.0038839148 | O7: 2010 | AD7: 2011
A8: 38868 | B8: 11169.1 | C8: =(B8/B7-1)/(A8-A7)*30 -> 0.004110966 | O8: 2011 | AD8: 2012
A9: 38898 | B9: 11215.04 | C9: =(B9/B8-1)/(A9-A8)*30 -> 0.0041131336 | O9: 2012 | AD9: 2013
A10: 38929 | B10: 11263.22 | C10: =(B10/B9-1)/(A10-A9)*30 -> 0.0041574356 | O10: 2013 | AD10: 2014
A11: 38960 | B11: 11313.29 | C11: =(B11/B10-1)/(A11-A10)*30 -> 0.0043020414 | O11: 2014 | AD11: 2015
A12: 38989 | B12: 11360.92 | C12: =(B12/B11-1)/(A12-A11)*30 -> 0.0043552683 | O12: 2015 | AD12: 2016
A13: 39021 | B13: 11413.02 | C13: =(B13/B12-1)/(A13-A12)*30 -> 0.0042992777 | O13: 2016 | AD13: 2017
A14: 39051 | B14: 11463.01 | C14: =(B14/B13-1)/(A14-A13)*30 -> 0.0043800852 | O14: 2017 | AD14: 2018
A15: 39080 | B15: 11512.49 | C15: =(B15/B14-1)/(A15-A14)*30 -> 0.0044653374 | O15: 2018 | AD15: 2019 | AR15: (*)
A16: 39113 | B16: 11567.23 | C16: =(B16/B15-1)/(A16-A15)*30 -> 0.004322578 | O16: 2019 | AD16: 2020
A17: 39141 | B17: 11612.68 | C17: =(B17/B16-1)/(A17-A16)*30 -> 0.0042098608 | O17: 2020 | AD17: 2021
A18: 39171 | B18: 11661.5 | C18: =(B18/B17-1)/(A18-A17)*30 -> 0.0042040253 | O18: 2021 | AD18: 2022 | AX18: -1 | AY18: -3 | AZ18: -6 | BA18: -12
A19: 39202 | B19: 11712.58 | C19: =(B19/B18-1)/(A19-A18)*30 -> 0.0042389279 | O19: 2022 | AD19: 2023 | AV19: Ingresar mes actual==> | AW19: 46142 | AX19: =EOMONTH($AW19,AX18)+6+1 -> 46119 | AY19: =EOMONTH($AW19,AY18) -> 46053 | AZ19: =EOMONTH($AW19,AZ18) -> 45961 | BA19: =EOMONTH($AW19,BA18) -> 45777 | BB19: 43100
A20: 39233 | B20: 11763.78 | C20: =(B20/B19-1)/(A20-A19)*30 -> 0.0042303563 | O20: 2023 | AD20: 2024 | AV20: ICP | AW20: =LOOKUP(AW19,$A$3:$A$2973,$B$3:$B$2973) -> 19916.85 | AX20: =LOOKUP(AX19,$A$3:$A$2973,$B$3:$B$2973) -> 26333.64 | AY20: =LOOKUP(AY19,$A$3:$A$2973,$B$3:$B$2973) -> 26136.9 | AZ20: =LOOKUP(AZ19,$A$3:$A$2973,$B$3:$B$2973) -> 25829.5 | BA20: =LOOKUP(BA19,$A$3:$A$2973,$B$3:$B$2973) -> 25197.48 | BB20: =LOOKUP(BB19,$A$3:$A$2973,$B$3:$B$2973) -> 17872.44
A21: 39262 | B21: 11812.23 | C21: =(B21/B20-1)/(A21-A20)*30 -> 0.0042605939 | O21: 2024 | AA21: 24777.58 | AD21: 2025 | AE21: =+P22/AA21-1 -> 0.0044544302 | AF21: =+Q22/P22-1 -> 0.0038962631 | AG21: =+R22/Q22-1 -> 0.0043138021 | AH21: =+S22/R22-1 -> 0.0041757164 | AI21: =+T22/S22-1 -> 0.0041742269 | AJ21: =+U22/T22-1 -> 0.0043145661 | AK21: =+V22/U22-1 -> 0.0043062621 | AL21: =+W22/V22-1 -> 0.0038332747 | AM21: =+X22/W22-1 -> 0.0042300488 | ... AP21: =+AA22/Z22-1 -> 0.004139462 | AQ21: =+(AA22/P22-1)/COUNTA(AE21:AP21)*12 -> 0.046121517 | AV21: Competencia | AW21: =LOOKUP(AW19,$F$2:$F$2974,$K$2:$K$2974) -> 0 | AX21: =LOOKUP(AX19,$F$2:$F$2974,$K$2:$K$2974) -> 6335.4774 | AY21: =LOOKUP(AY19,$F$2:$F$2974,$K$2:$K$2974) -> 6303.0823 | AZ21: =LOOKUP(AZ19,$F$2:$F$2974,$K$2:$K$2974) -> 6250.6982 | BA21: =LOOKUP(BA19,$F$2:$F$2974,$K$2:$K$2974) -> 6141.4105 | BB21: =LOOKUP(BB19,$F$2:$F$2974,$K$2:$K$2974) -> 1066.0204
A22: 39294 | B22: 11866.53 | C22: =(B22/B21-1)/(A22-A21)*30 -> 0.0043096223 | O22: 2025 | P22: =+B234 -> 24887.95 | Q22: =+B235 -> 24984.92 | R22: =+B236 -> 25092.7 | S22: =+B237 -> 25197.48 | T22: =+B238 -> 25302.66 | U22: =+B239 -> 25411.83 | V22: =+B240 -> 25521.26 | W22: =+B241 -> 25619.09 | X22: =+B242 -> 25727.46 | Y22: =+B243 -> 25829.5 | Z22: =+B244 -> 25928.49 | AA22: =+B245 -> 26035.82 | AD22: 2026 | AE22: =+P23/AA22-1 -> 0.0038823436 | AF22: =+Q23/P23-1 -> 0.0036312646 | AG22: =+R23/Q23-1 -> 0.0038819281 | AH22: =+S23/R23-1 -> -0.24367272 | AQ22: =+(S23/P23-1)/COUNTA(AE22:AP22)*12 -> -0.71393889 | AV22: FIP Liquidez Activa | AW22: =LOOKUP(AW19,$F$2:$F$2972,$H$2:$H$2972) -> 1070.5872 | AX22: =LOOKUP(AX19,$F$2:$F$2972,$H$2:$H$2972) -> 1064.2617 | AY22: =LOOKUP(AY19,$F$2:$F$2972,$H$2:$H$2972) -> 1051.9576 | AZ22: =LOOKUP(AZ19,$F$2:$F$2972,$H$2:$H$2972) -> 1033.2547 | BA22: =LOOKUP(BA19,$F$2:$F$2972,$H$2:$H$2972) -> 1000 | BB22: =LOOKUP(BB19,$F$2:$F$2972,$H$2:$H$2972) -> 0
O23: 2026 | P23: =+B246 -> 26136.9 | Q23: =+B247 -> 26231.81 | R23: =+B248 -> 26333.64 | S23: =+B249 -> 19916.85 | AD23: (*) Acum a Mar
A24: 39325 | B24: 11922.48 | C24: =(B24/B22-1)/(A24-A22)*30 -> 0.004562847 | P24: 31 | Q24: 28 | R24: 31 | S24: 30 | T24: 31 | U24: 30 | V24: 31 | W24: 31 | X24: 30 | Y24: 31 | Z24: 30 | AA24: 31
A25: 39353 | B25: 11975.61 | C25: =(B25/B24-1)/(A25-A24)*30 -> 0.0047745939 | P25: 1 | Q25: 2 | R25: 3 | S25: 4 | T25: 5 | U25: 6 | V25: 7 | W25: 8 | X25: 9 | Y25: 10 | Z25: 11 | AA25: 12
A26: 39386 | B26: 12038.9 | C26: =(B26/B25-1)/(A26-A25)*30 -> 0.004804462 | O26: FONDO LIQUIDEZ ACTIVA | P26: Ene | Q26: Feb | R26: Mar | S26: Abr | T26: May | U26: Jun | V26: Jul | W26: Ago | X26: Sep | Y26: Oct | Z26: Nov | AA26: Dic
A27: 39416 | B27: 12096.85 | C27: =(B27/B26-1)/(A27-A26)*30 -> 0.0048135627 | O27: 2016 | T27: - | U27: =LOOKUP(DATE($O27,U$25,U$24),$A$2:$A$2943,$H$2:$H$2943) -> 0 | V27: =LOOKUP(DATE($O27,V$25,V$24),$A$2:$A$2943,$H$2:$H$2943) -> 0 | W27: =LOOKUP(DATE($O27,W$25,W$24),$A$2:$A$2943,$H$2:$H$2943) -> 0 | X27: =LOOKUP(DATE($O27,X$25,X$24),$A$2:$A$2943,$H$2:$H$2943) -> 0 | Y27: =LOOKUP(DATE($O27,Y$25,Y$24),$A$2:$A$2943,$H$2:$H$2943) -> 0 | Z27: =LOOKUP(DATE($O27,Z$25,Z$24),$A$2:$A$2943,$H$2:$H$2943) -> 0 | AA27: =LOOKUP(DATE($O27,AA$25,AA$24),$A$2:$A$2943,$H$2:$H$2943) -> 0 | AD27: ACTIVA | AE27: Ene | AF27: Feb | AG27: Mar | AH27: Abr | AI27: May | AJ27: Jun | AK27: Jul | AL27: Ago | AM27: Sep | AN27: Oct | AO27: Nov | AP27: Dic | AQ27: Total Año
A28: 39447 | B28: 12152.6 | C28: =(B28/B27-1)/(A28-A27)*30 -> 0.0044599721 | O28: 2017 | P28: =LOOKUP(DATE($O28,P$25,P$24),$A$2:$A$2943,$H$2:$H$2943) -> 0 | Q28: =LOOKUP(DATE($O28,Q$25,Q$24),$A$2:$A$2943,$H$2:$H$2943) -> 0 | R28: =LOOKUP(DATE($O28,R$25,R$24),$A$2:$A$2943,$H$2:$H$2943) -> 0 | S28: =LOOKUP(DATE($O28,S$25,S$24),$A$2:$A$2943,$H$2:$H$2943) -> 0 | T28: =LOOKUP(DATE($O28,T$25,T$24),$A$2:$A$2943,$H$2:$H$2943) -> 0 | U28: =LOOKUP(DATE($O28,U$25,U$24),$A$2:$A$2943,$H$2:$H$2943) -> 0 | V28: =LOOKUP(DATE($O28,V$25,V$24),$A$2:$A$2943,$H$2:$H$2943) -> 0 | W28: =LOOKUP(DATE($O28,W$25,W$24),$A$2:$A$2943,$H$2:$H$2943) -> 0 | ... AA28: =LOOKUP(DATE($O28,AA$25,AA$24),$A$2:$A$2943,$H$2:$H$2943) -> 0 | AD28: 2016 | AW28: Rentabilidad | AX28: Mensual | AY28: Trimestral | AZ28: Semestral | BA28: Anual | BB28: Acum. 2026
A29: 39478 | B29: 12223.14 | C29: =(B29/B28-1)/(A29-A28)*30 -> 0.0056172766 | O29: 2018 | P29: =LOOKUP(DATE($O29,P$25,P$24),$A$2:$A$2943,$H$2:$H$2943) -> 0 | Q29: =LOOKUP(DATE($O29,Q$25,Q$24),$A$2:$A$2943,$H$2:$H$2943) -> 0 | R29: =LOOKUP(DATE($O29,R$25,R$24),$A$2:$A$2943,$H$2:$H$2943) -> 0 | S29: =LOOKUP(DATE($O29,S$25,S$24),$A$2:$A$2943,$H$2:$H$2943) -> 0 | T29: =LOOKUP(DATE($O29,T$25,T$24),$A$2:$A$2943,$H$2:$H$2943) -> 0 | U29: =LOOKUP(DATE($O29,U$25,U$24),$A$2:$A$2943,$H$2:$H$2943) -> 0 | V29: =LOOKUP(DATE($O29,V$25,V$24),$A$2:$A$2943,$H$2:$H$2943) -> 0 | W29: =LOOKUP(DATE($O29,W$25,W$24),$A$2:$A$2943,$H$2:$H$2943) -> 0 | ... AA29: =LOOKUP(DATE($O29,AA$25,AA$24),$A$2:$A$2943,$H$2:$H$2943) -> 0 | AD29: 2017 | AR29: (*) | AW29: ICP (Bechmark) | AX29: =$AW20/AX20-1 -> -0.24367272 | AY29: =$AW20/AY20-1 -> -0.23797963 | AZ29: =$AW20/AZ20-1 -> -0.22891073 | BA29: =$AW20/BA20-1 -> -0.20956976 | BB29: =+AQ86 -> -0.71393889
A30: 39507 | B30: 12284.88 | C30: =(B30/B29-1)/(A30-A29)*30 -> 0.0052252503 | O30: 2019 | P30: =LOOKUP(DATE($O30,P$25,P$24),$A$2:$A$2943,$H$2:$H$2943) -> 0 | Q30: =LOOKUP(DATE($O30,Q$25,Q$24),$A$2:$A$2943,$H$2:$H$2943) -> 0 | R30: =LOOKUP(DATE($O30,R$25,R$24),$A$2:$A$2943,$H$2:$H$2943) -> 0 | S30: =LOOKUP(DATE($O30,S$25,S$24),$A$2:$A$2943,$H$2:$H$2943) -> 0 | T30: =LOOKUP(DATE($O30,T$25,T$24),$A$2:$A$2943,$H$2:$H$2943) -> 0 | U30: =LOOKUP(DATE($O30,U$25,U$24),$A$2:$A$2943,$H$2:$H$2943) -> 0 | V30: =LOOKUP(DATE($O30,V$25,V$24),$A$2:$A$2943,$H$2:$H$2943) -> 0 | W30: =LOOKUP(DATE($O30,W$25,W$24),$A$2:$A$2943,$H$2:$H$2943) -> 0 | ... AA30: =LOOKUP(DATE($O30,AA$25,AA$24),$A$2:$A$2943,$H$2:$H$2943) -> 0 | AD30: 2018 | AW30: Competencia | AX30: =$AW21/AX21-1 -> -1 | AY30: =$AW21/AY21-1 -> -1 | AZ30: =$AW21/AZ21-1 -> -1 | BA30: =$AW21/BA21-1 -> -1 | BB30: =+AQ87 -> -3
A31: 39538 | B31: 12351.45 | C31: =(B31/B30-1)/(A31-A30)*30 -> 0.0052440545 | O31: 2020 | P31: =LOOKUP(DATE($O31,P$25,P$24),$A$2:$A$2943,$H$2:$H$2943) -> 0 | Q31: =LOOKUP(DATE($O31,Q$25,Q$24)+1,$A$2:$A$2943,$H$2:$H$2943) -> 0 | R31: =LOOKUP(DATE($O31,R$25,R$24)+1,$A$2:$A$2943,$H$2:$H$2943) -> 0 | S31: =LOOKUP(DATE($O31,S$25,S$24)+1,$A$2:$A$2943,$H$2:$H$2943) -> 0 | T31: =LOOKUP(DATE($O31,T$25,T$24)+1,$A$2:$A$2943,$H$2:$H$2943) -> 0 | U31: =LOOKUP(DATE($O31,U$25,U$24)+1,$A$2:$A$2943,$H$2:$H$2943) -> 0 | V31: =LOOKUP(DATE($O31,V$25,V$24)+1,$A$2:$A$2943,$H$2:$H$2943) -> 0 | W31: =LOOKUP(DATE($O31,W$25,W$24)+1,$A$2:$A$2943,$H$2:$H$2943) -> 0 | X31: =LOOKUP(DATE($O31,X$25,X$24)+1,$A$2:$A$2943,$H$2:$H$2943) -> 0 | Y31: =+H183 -> 0 | Z31: =+H184 -> 0 | AA31: =+H185 -> 0 | AD31: 2019 | AW31: FIP LIQUIDEZ ACTIVA | AX31: =$AW22/AX22-1 -> 0.0059435569 | AY31: =IFERROR(($AW22/AY22-1),0) -> 0.017709459 | AZ31: =IFERROR(($AW22/AZ22-1),0) -> 0.036130975 | BA31: =$AW22/BA22-1 -> 0.0705872 | BB31: =+AQ88 -> 0.053128377
A32: 39568 | B32: 12416.18 | C32: =(B32/B31-1)/(A32-A31)*30 -> 0.0052406802 | O32: 2021 | AD32: 2020
A33: 39598 | B33: 12481.48 | C33: =(B33/B32-1)/(A33-A32)*30 -> 0.0052592665 | O33: 2022 | AD33: 2021
A34: 39629 | B34: 12552.23 | C34: =(B34/B33-1)/(A34-A33)*30 -> 0.0054855467 | O34: 2023 | AD34: 2022
A35: 39660 | B35: 12628.9 | C35: =(B35/B34-1)/(A35-A34)*30 -> 0.0059110432 | O35: 2024 | AA35: 0 | AD35: 2023
A36: 39689 | B36: 12704.63 | C36: =(B36/B35-1)/(A36-A35)*30 -> 0.0062033415 | O36: 2025 | P36: =+H236 -> 999 | Q36: =+G236 -> 999 | R36: =+H236 -> 999 | S36: =+H237 -> 1000 | T36: =+H238 -> 1000.8554 | U36: =+H239 -> 1008.2272 | V36: =+H240 -> 1014.4794 | W36: =+H241 -> 1020.691 | X36: =+H242 -> 1026.5784 | Y36: =+H243 -> 1033.2547 | Z36: =+H244 -> 1039.2601 | AA36: =+H245 -> 1045.7936 | AD36: 2024
O37: 2026 | P37: =+H246 -> 1051.9576 | Q37: =+H247 -> 1057.7544 | R37: =+H248 -> 1064.2617 | S37: =+H249 -> 1070.5872 | AD37: 2025 | AE37: 0 | AF37: =+(Q36/P36-1) -> 0 | AG37: =+(R36/Q36-1) -> 0 | AH37: =+(S36/R36-1) -> 0.001001001 | AI37: =+(T36/S36-1) -> 0.0008554 | AJ37: =+(U36/T36-1) -> 0.0073654996 | AK37: =+(V36/U36-1) -> 0.0062011816 | AL37: =+(W36/V36-1) -> 0.0061229435 | AM37: =+(X36/W36-1) -> 0.0057680532 | ... AP37: =+(AA36/Z36-1) -> 0.0062866842 | AQ37: =+(AA36/P36-1)/COUNTA(AE37:AP37)*12 -> 0.04684044
A38: 39721 | B38: 12796.95 | C38: =(B38/B36-1)/(A38-A36)*30 -> 0.006812477 | P38: 31 | Q38: 28 | R38: 31 | S38: 30 | T38: 31 | U38: 30 | V38: 31 | W38: 31 | X38: 30 | Y38: 31 | Z38: 30 | AA38: 31 | AD38: 2026 | AE38: =+(P37/AA36-1) -> 0.0058940885 | AF38: =+(Q37/P37-1) -> 0.0055104883 | AG38: =+(R37/Q37-1) -> 0.0061519952 | AH38: =+(S37/R37-1) -> 0.0059435569 | AQ38: =+(S37/P37-1)/COUNTA(AE38:AP38)*12 -> 0.053128377 | AR38: (*)
A39: 39752 | B39: 12885.37 | C39: =(B39/B38-1)/(A39-A38)*30 -> 0.0066865731 | P39: 1 | Q39: 2 | R39: 3 | S39: 4 | T39: 5 | U39: 6 | V39: 7 | W39: 8 | X39: 9 | Y39: 10 | Z39: 11 | AA39: 12 | AD39: (*) Acum a Mar
A40: 39780 | B40: 12970.93 | C40: =(B40/B39-1)/(A40-A39)*30 -> 0.0071143808 | O40: Competencia | P40: Ene | Q40: Feb | R40: Mar | S40: Abr | T40: May | U40: Jun | V40: Jul | W40: Ago | X40: Sep | Y40: Oct | Z40: Nov | AA40: Dic | AD40: Competencia | AE40: Ene | AF40: Feb | AG40: Mar | AH40: Abr | AI40: May | AJ40: Jun | AK40: Jul | AL40: Ago | AM40: Sep | AN40: Oct | AO40: Nov | AP40: Dic | AQ40: Total Año
...

Sheet rentabilidad
S1: Rentabilidad | T1: Mensual | U1: Trimestral | V1: Semestral | W1: Anual | X1: Acum 2026 (*)
S2: ICP (Benchmark) | T2: =+'Datos ICP (2)'!AX29 -> -0.24367272 | U2: =+'Datos ICP (2)'!AY29 -> -0.23797963 | V2: =+'Datos ICP (2)'!AZ29 -> -0.22891073 | X2: =+'Datos ICP (2)'!BB29 -> -0.71393889
S3: Competencia | T3: =+'Datos ICP (2)'!AX30 -> -1 | U3: =+'Datos ICP (2)'!AY30 -> -1 | V3: =+'Datos ICP (2)'!AZ30 -> -1 | X3: =+'Datos ICP (2)'!BB30 -> -3
S4: FIP LIQUIDEZ ACTIVA | T4: =+'Datos ICP (2)'!AX31 -> 0.0059435569 | U4: =+'Datos ICP (2)'!AY31 -> 0.017709459 | V4: =+'Datos ICP (2)'!AZ31 -> 0.036130975 | X4: =+'Datos ICP (2)'!BB31 -> 0.053128377
C6: Año | D6: Fondo | E6: Ene | F6: Feb | G6: Mar | H6: Abr | I6: May | J6: Jun | K6: Jul | L6: Ago | M6: Sep | N6: Oct | O6: Nov | P6: Dic | Q6: Total Año
C8: 2013 | D8: ICP
C9: 2014 | D9: ICP
C10: 2015 | D10: ICP
C11: 2016 | D11: ICP
C12: 2017 | D12: ICP
D13: Competencia
D14: FIP LIQUIDEZ Continua
C15: 2018 | D15: ICP
D16: Competencia
D17: FIP LIQUIDEZ Continua
C18: 2019 | D18: ICP
D19: Competencia
D20: FIP LIQUIDEZ Continua
C21: 2020 | D21: ICP
D22: Competencia
D23: FIP LIQUIDEZ Continua
C24: 2021 | D24: ICP
D25: Competencia
D26: FIP LIQUIDEZ Continua
C27: 2022 | D27: ICP
D28: Competencia
D29: FIP LIQUIDEZ Continua
C30: 2023 | D30: ICP | M30: =+'Datos ICP (2)'!AM77 -> 0 | N30: =+'Datos ICP (2)'!AN77 -> 0 | O30: =+'Datos ICP (2)'!AO77 -> 0 | P30: =+'Datos ICP (2)'!AP77 -> 0 | Q30: =+'Datos ICP (2)'!AQ77 -> 0
D31: Competencia | M31: =+'Datos ICP (2)'!AM78 -> 0 | N31: =+'Datos ICP (2)'!AN78 -> 0 | O31: =+'Datos ICP (2)'!AO78 -> 0 | P31: =+'Datos ICP (2)'!AP78 -> 0 | Q31: =+'Datos ICP (2)'!AQ78 -> 0
D32: FIP LIQUIDEZ ACTIVA | M32: =+'Datos ICP (2)'!AM79 -> 0 | N32: =+'Datos ICP (2)'!AN79 -> 0 | O32: =+'Datos ICP (2)'!AO79 -> 0 | P32: =+'Datos ICP (2)'!AP79 -> 0 | Q32: =+'Datos ICP (2)'!AQ79 -> 0
C33: 2024 | D33: ICP | E33: =+'Datos ICP (2)'!AE80 -> 0 | F33: =+'Datos ICP (2)'!AF80 -> 0 | G33: =+'Datos ICP (2)'!AG80 -> 0 | H33: =+'Datos ICP (2)'!AH80 -> 0 | I33: =+'Datos ICP (2)'!AI80 -> 0 | J33: =+'Datos ICP (2)'!AJ80 -> 0 | K33: =+'Datos ICP (2)'!AK80 -> 0 | L33: =+'Datos ICP (2)'!AL80 -> 0 | ... Q33: =+'Datos ICP (2)'!AQ80 -> 0
D34: Competencia | E34: =+'Datos ICP (2)'!AE81 -> 0 | F34: =+'Datos ICP (2)'!AF81 -> 0 | G34: =+'Datos ICP (2)'!AG81 -> 0 | H34: =+'Datos ICP (2)'!AH81 -> 0 | I34: =+'Datos ICP (2)'!AI81 -> 0 | J34: =+'Datos ICP (2)'!AJ81 -> 0 | K34: =+'Datos ICP (2)'!AK81 -> 0 | L34: =+'Datos ICP (2)'!AL81 -> 0 | ... Q34: =+'Datos ICP (2)'!AQ81 -> 0
D35: FIP LIQUIDEZ ACTIVA | E35: =+'Datos ICP (2)'!AE82 -> 0 | F35: =+'Datos ICP (2)'!AF82 -> 0 | G35: =+'Datos ICP (2)'!AG82 -> 0 | H35: =+'Datos ICP (2)'!AH82 -> 0 | I35: =+'Datos ICP (2)'!AI82 -> 0 | J35: =+'Datos ICP (2)'!AJ82 -> 0 | K35: =+'Datos ICP (2)'!AK82 -> 0 | L35: =+'Datos ICP (2)'!AL82 -> 0 | ... Q35: =+'Datos ICP (2)'!AQ82 -> 0
C36: 2025 | D36: ICP | E36: =+'Datos ICP (2)'!AE83 -> 0.0044544302 | F36: =+'Datos ICP (2)'!AF83 -> 0.0038962631 | G36: =+'Datos ICP (2)'!AG83 -> 0.0043138021 | H36: =+'Datos ICP (2)'!AH83 -> 0.0041757164 | I36: =+'Datos ICP (2)'!AI83 -> 0.0041742269 | J36: =+'Datos ICP (2)'!AJ83 -> 0.0043145661 | K36: =+'Datos ICP (2)'!AK83 -> 0.0043062621 | L36: =+'Datos ICP (2)'!AL83 -> 0.0038332747 | ... Q36: =+'Datos ICP (2)'!AQ83 -> 0.046121517
D37: Competencia | E37: =+'Datos ICP (2)'!AE84 -> 0.0030202103 | F37: =+'Datos ICP (2)'!AF84 -> 0.0027621377 | G37: =+'Datos ICP (2)'!AG84 -> 0.0030628269 | H37: =+'Datos ICP (2)'!AH84 -> 0.0029759497 | I37: =+'Datos ICP (2)'!AI84 -> 0.0030897625 | J37: =+'Datos ICP (2)'!AJ84 -> 0.0029970525 | K37: =+'Datos ICP (2)'!AK84 -> 0.0030490145 | L37: =+'Datos ICP (2)'!AL84 -> 0.002902082 | ... Q37: =+'Datos ICP (2)'!AQ84 -> 0.032570786
D38: FIP LIQUIDEZ ACTIVA | E38: =+'Datos ICP (2)'!AE85 -> 0 | F38: =+'Datos ICP (2)'!AF85 -> 0 | G38: =+'Datos ICP (2)'!AG85 -> 0 | H38: =+'Datos ICP (2)'!AH85 -> 0.001001001 | I38: =+'Datos ICP (2)'!AI85 -> 0.0008554 | J38: =+'Datos ICP (2)'!AJ85 -> 0.0073654996 | K38: =+'Datos ICP (2)'!AK85 -> 0.0062011816 | L38: =+'Datos ICP (2)'!AL85 -> 0.0061229435 | ... Q38: =+'Datos ICP (2)'!AQ85 -> 0.04684044
C39: 2026 | D39: ICP | E39: =+'Datos ICP (2)'!AE86 -> 0.0038823436 | F39: =+'Datos ICP (2)'!AF86 -> 0.0036312646 | G39: =+'Datos ICP (2)'!AG86 -> 0.0038819281 | H39: =+'Datos ICP (2)'!AH86 -> -0.24367272 | Q39: =+'Datos ICP (2)'!AQ86 -> -0.71393889
D40: Competencia | E40: =+'Datos ICP (2)'!AE87 -> 0.0027244382 | F40: =+'Datos ICP (2)'!AF87 -> 0.0024452164 | G40: =+'Datos ICP (2)'!AG87 -> 0.0026877763 | H40: =+'Datos ICP (2)'!AH87 -> -1 | Q40: =+'Datos ICP (2)'!AQ87 -> -3
D41: FIP LIQUIDEZ ACTIVA | E41: =+'Datos ICP (2)'!AE88 -> 0.0058940885 | F41: =+'Datos ICP (2)'!AF88 -> 0.0055104883 | G41: =+'Datos ICP (2)'!AG88 -> 0.0061519952 | H41: =+'Datos ICP (2)'!AH88 -> 0.0059435569 | Q41: =+'Datos ICP (2)'!AQ88 -> 0.053128377

Sheet composición
J1: Duración | N1: Instrumentos | R1: Moneda
O2: Bono | P2: 0
K3: Menos de 1 mes | L3: 0.6316 | O3: Depósitos | P3: 0 | S3: Pesos | T3: 1
K4: 1-3 meses | L4: 0.28 | O4: Factoring | P4: 0 | S4: UF | T4: 0
K5: 3-4 meses | L5: 0.0884 | O5: Financiamiento Inmobiliario | P5: 0
K6: Más de 4 meses | L6: 0 | O6: Financiamiento Mesa Moneda Extranjera | P6: 1
L7: =SUM(L3:L6) -> 1 | O7: Garantías | P7: 0
O8: Nota Estructurada | P8: 0
O9: Financiamiento Mesa Renta Fija | P9: 0
O10: Simultánea | P10: 0
O11: Efectos de Comercio | P11: 0
O13: Pagaré | P13: 0
A14: Facturas | B14: 0
P15: =SUM(P2:P14) -> 1
